pytest允许您使用标准python断言来验证python测试中的期望和值。例如，您可以编写以下代码:

    # content of test_assert1.py
    def f():
        return 3
    

    def test_function():
        assert f() == 4

以断言函数返回某个值。如果此断言失败，您将看到函数调用的返回值：

    $ pytest test_assert1.py
    =========================== test session starts ============================
    platform linux -- Python 3.x.y, pytest-5.x.y, py-1.x.y, pluggy-0.x.y
    cachedir: $PYTHON_PREFIX/.pytest_cache
    rootdir: $REGENDOC_TMPDIR
    collected 1 item

    test_assert1.py F                                                    [100%]

    ================================= FAILURES =================================
    ______________________________ test_function _______________________________

        def test_function():
    >       assert f() == 4
    E       assert 3 == 4
    E        +  where 3 = f()

    test_assert1.py:6: AssertionError
    ========================= short test summary info ==========================
    FAILED test_assert1.py::test_function - assert 3 == 4
    ============================ 1 failed in 0.12s =============================

`pytest`支持显示最常见的子表达式的值，包括调用、属性、比较以及二进制和一元操作符。(参见[使用pytest的Python失败报告演示](https://docs.pytest.org/en/latest/example/reportingdemo.html#tbreportdemo))。这允许您在没有样板代码的情况下使用惯用的python构造，同时不丢失自省信息。

但是，如果您像这样用断言指定一条消息:

    assert a % 2 == 0, "value was odd, should be even"

那么就不会进行任何声明自省，并且消息将简单地显示在回溯中。

有关断言内省的更多信息，请参见[断言内省详细信息](https://docs.pytest.org/en/latest/assert.html#assert-details)。

#### 关于预期异常的断言
为了编写有关引发的异常的断言，可以将pytest.raises用作上下文管理器，如下所示：

    import pytest
    

    def test_zero_division():
        with pytest.raises(ZeroDivisionError):
            1 / 0

如果你需要访问实际的异常信息，你可以使用:

    def test_recursion_depth():
        with pytest.raises(RuntimeError) as excinfo:

            def f():
                f()

            f()
        assert "maximum recursion" in str(excinfo.value)

`excinfo`是一个`ExceptionInfo`实例，它是实际抛出的异常的包装器。关注的主要属性是`.type`、`.value`和`.traceback`。

您可以将match关键字参数传递给上下文管理器，以测试正则表达式是否与异常的字符串表示形式匹配（类似于`unittest`的`TestCase.assertRaisesRegexp`方法）:

    import pytest
    

    def myfunc():
        raise ValueError("Exception 123 raised")
    

    def test_match():
        with pytest.raises(ValueError, match=r".* 123 .*"):
            myfunc()

match方法的regexp参数与`re.search`函数相匹配，因此在上面的示例中match='123'也可以工作。

pytest.raises函数有另一种形式，您传递一个函数，该函数将使用给定的* args和** kwargs执行，并断言给定的异常已引发：

    pytest.raises(ExpectedException, func, *args, **kwargs)

如果出现失败的情况，例如没有异常或错误异常，报告器将为您提供有用的输出。  

请注意，还可以为`pytest.mark.xfail`指定一个“raises”参数，它会检查测试失败的具体方式，而不仅仅是抛出任何异常:

    @pytest.mark.xfail(raises=IndexError)
    def test_f():
        f()

在测试异常的情况下，使用`pytest.raises`使您的代码刻意抛出异常可能会更好，而将`@pytest.mark.xfail`与检查功能配合使用可能更适合记录未修复的错误（测试描述了应该发生的情况）或依赖项中的错误。

#### 关于预期警告的断言
您可以使用[pytest.warns](https://docs.pytest.org/en/latest/warnings.html#warns)检查代码是否引发了特定的警告。

#### 利用上下文相关的比较
`pytest`在遇到比较时提供了上下文相关信息的丰富支持。例如：

    # content of test_assert2.py

    def test_set_comparison():
        set1 = set("1308")
        set2 = set("8035")
        assert set1 == set2

如果您运行该模块：

    $ pytest test_assert2.py
    =========================== test session starts ============================
    platform linux -- Python 3.x.y, pytest-5.x.y, py-1.x.y, pluggy-0.x.y
    cachedir: $PYTHON_PREFIX/.pytest_cache
    rootdir: $REGENDOC_TMPDIR
    collected 1 item

    test_assert2.py F                                                    [100%]

    ================================= FAILURES =================================
    ___________________________ test_set_comparison ____________________________

        def test_set_comparison():
            set1 = set("1308")
            set2 = set("8035")
    >       assert set1 == set2
    E       AssertionError: assert {'0', '1', '3', '8'} == {'0', '3', '5', '8'}
    E         Extra items in the left set:
    E         '1'
    E         Extra items in the right set:
    E         '5'
    E         Use -v to get the full diff

    test_assert2.py:6: AssertionError
    ========================= short test summary info ==========================
    FAILED test_assert2.py::test_set_comparison - AssertionError: assert {'0'...
    ============================ 1 failed in 0.12s =============================

对一些情况进行了特殊的比较:

* 比较长字符串:显示上下文差异
* 比较长序列：第一个失败的索引
* 比较字典：不同的条目

有关更多示例，请参见[演示报告](https://docs.pytest.org/en/latest/example/reportingdemo.html#tbreportdemo)。

#### 为失败的断言定义自己的解释

可以通过实现`pytest_assertrepr_compare`钩子来添加您自己的详细解释。

pytest_assertrepr_compare(config, op, left, right)&nbsp; &nbsp; &nbsp; &nbsp; &nbsp; &nbsp; &nbsp; &nbsp; &nbsp; &nbsp; &nbsp; &nbsp; &nbsp; &nbsp; &nbsp; &nbsp; &nbsp; &nbsp; &nbsp; &nbsp; &nbsp; &nbsp; &nbsp; &nbsp; &nbsp; &nbsp; [[source]](https://docs.pytest.org/en/latest/_modules/_pytest/hookspec.html#pytest_assertrepr_compare)

返回对失败的断言表达式进行比较的说明。

如果没有自定义说明，则返回None，否则返回字符串列表。字符串将由换行符连接，但字符串中的任何换行符都将被转义。注意，除了第一行之外，所有的行都将略微缩进，目的是让第一行成为一个概括。

**Parameters:	config** ([_pytest.config.Config](https://docs.pytest.org/en/latest/reference.html#_pytest.config.Config)) – pytest config object

例如，考虑在conftest.py文件中添加以下钩子，该钩子为Foo对象提供了另一种解释：

    # content of conftest.py
    from test_foocompare import Foo
    

    def pytest_assertrepr_compare(op, left, right):
        if isinstance(left, Foo) and isinstance(right, Foo) and op == "==":
            return [
                "Comparing Foo instances:",
                "   vals: {} != {}".format(left.val, right.val),
            ]

现在，由于此测试模块：

    # content of test_foocompare.py
    class Foo:
        def __init__(self, val):
            self.val = val
    
        def __eq__(self, other):
            return self.val == other.val
    

    def test_compare():
        f1 = Foo(1)
        f2 = Foo(2)
        assert f1 == f2

您可以运行测试模块并获取在conftest文件中定义的自定义输出：

    $ pytest -q test_foocompare.py
    F                                                                    [100%]
    ================================= FAILURES =================================
    _______________________________ test_compare _______________________________

        def test_compare():
            f1 = Foo(1)
            f2 = Foo(2)
    >       assert f1 == f2
    E       assert Comparing Foo instances:
    E            vals: 1 != 2

    test_foocompare.py:12: AssertionError
    ========================= short test summary info ==========================
    FAILED test_foocompare.py::test_compare - assert Comparing Foo instances:
    1 failed in 0.12s

#### 断言自省的详细信息

报告失败断言的详细信息是通过在运行断言语句之前重写断言语句来实现的。重写的断言语句将自省信息放入断言失败消息中。pytest只重写由它的测试收集过程直接发现的测试模，因此支持模块中本身不是测试模块的断言将不会被重写。

您可以在导入模块之前调用[register_assert_rewrite](https://docs.pytest.org/en/latest/writing_plugins.html#assertion-rewriting)来手动启用已导入模块的断言重写(最好是在您的根`conftest.py`中)。

为了获得更多的信息，Benjamin Peterson撰写了 [Behind the scenes of pytest’s new assertion rewriting (pytest新断言重写的背后)](http://pybites.blogspot.com/2011/07/behind-scenes-of-pytests-new-assertion.html)

##### 断言重写在磁盘上缓存文件

`pytest`会将重写的模块写回到磁盘以进行缓存。您可以通过将此添加到`conftest.py`文件的顶部来禁用此行为(例如，以避免在经常移动文件的项目中留下陈旧的`.pyc`文件)

    import sys

    sys.dont_write_bytecode = True

请注意，您仍然可以获得断言自省的好处，唯一的变化是`.pyc`文件不会被缓存在磁盘上。

此外，如果不能在只读文件系统或zipfile中写入新的`.pyc`文件,重写将自动跳过缓存。

##### 禁用断言重写

pytest通过使用导入钩子来编写新的pyc文件，从而重写导入时的测试模块。大多数情况下，这是透明的。但是，如果您自己使用导入机器，则导入钩子可能会干扰。

如果是这种情况，您有两个选择：

* 通过将字符串`PYTEST_DONT_REWRITE`添加到其文档字符串来禁用特定模块的重写。
* 通过使用`--assert = plain`禁用所有模块的重写。
